<robot name="humanoid">
  <!-- ===== DUMMY 'BASE' LINK ==== -->
  <link name="torso">
    <inertial>
      <mass value="6.5"/>
      <origin xyz="0.0 0.0 0.15"/>
      <inertia ixx="0.3006167" ixy="0" ixz="0" iyy="0.23837" iyz="0" izz="0.09690467"/>
    </inertial>
    <visual>
      <geometry>
         <mesh filename="meshes/Body.dae" scale="1 1 1"/>
      </geometry>
      <origin rpy="-1.5707 0 0" xyz="0 0 0"/>
    </visual>
  </link>
  <!--!!!!!!!!!!!!!!!!!!!!!RIGHT LEG!!!!!!!!!!!!!!!!!!!!!!!!!!!!!!!!!!!!!!!!!!!!!!!!-->
  <joint name="r_hip_yaw" type="continuous">
    <axis xyz="0 0 1"/>
    <origin rpy="0 0 0" xyz="0.0 -0.090 -0.029"/>
    <parent link="torso"/>
    <child link="R_HIP_C"/>
  </joint>
  <link name="R_HIP_C">
    <inertial>
      <mass value="1.20717"/>
      <origin xyz="-0.00043 0.0 -0.05917"/>
      <inertia ixx="0.001996651" ixy="0.000000328" ixz="0.000040451" iyy="0.002472257" iyz="0.0" izz="0.001645947"/>
    </inertial>
      <visual>
        <geometry>
          <mesh filename="meshes_tello/HIP_C.dae" scale="1 1 1"/>
        </geometry>
        <origin rpy="0.0 0.0 0.0" xyz="0.0 0.0 0.0"/>
    </visual>
 </link>

  <joint name="r_hip_roll" type="continuous">
    <axis xyz="1 0 0"/>
    <origin rpy="0.0 0.0 0.0" xyz="0.0 0.0 -0.175"/>
    <parent link="R_HIP_C"/>
    <child link="R_HIP_GIMBAL"/>
  </joint>
  <link name="R_HIP_GIMBAL">
    <inertial>
      <mass value="0.26433"/>
      <origin xyz="-0.00152 0.0 0.01677"/>
      <inertia ixx="0.000735018" ixy="0.0" ixz="0.000001772" iyy="0.000715107" iyz="0.000000002" izz="0.000728669"/>
    </inertial>
      <visual>
        <geometry>
          <mesh filename="meshes_tello/HIP_GIMBAL.dae" scale="1 1 1"/>
        </geometry>
        <origin rpy="0.0 0.0 0.0" xyz="0.0 0.0 0.0"/>
    </visual>
 </link>


  <joint name="r_hip_pitch" type="continuous">
    <axis xyz="0 1 0"/>
    <origin rpy="0.0 0 0.0" xyz="0.0 0.0 -0.022"/>
    <parent link="R_HIP_GIMBAL"/>
    <child link="R_THIGH"/>
  </joint>

  <link name="R_THIGH">
    <inertial>
      <mass value="2.111"/>
      <origin xyz="-0.00525 0.00011 -0.03179"/>
      <inertia ixx="0.012171016" ixy="-0.000013456" ixz="-0.000145044" iyy="0.011789322" iyz="0.000027517" izz="0.003575467"/>
    </inertial>
     <visual>
       <geometry>
         <mesh filename="meshes_tello/THIGH.dae" scale="1 1 1"/>
       </geometry>
       <origin rpy="0.0 0.0 0.0" xyz="0.0 0.0 0.0"/>
    </visual>
  </link>

  <joint name="r_knee" type="continuous">
    <axis xyz="0 1 0"/>
    <!-- <origin rpy="0 0 0" xyz="0.0 0.0 -0.47"/> -->
    <origin rpy="0 0 0" xyz="0.0 0.0 -0.2276"/>
    <parent link="R_THIGH"/>
    <child link="R_SHANK" />
  </joint>

  <link name="R_SHANK">
    <inertial>
      <mass value="0.37773"/>
      <origin xyz="0.00396 -0.00016 -0.098.34"/>
      <inertia ixx="0.001797413" ixy="0.000002934" ixz="0.000019506" iyy="0.001815537" iyz="0.000003553" izz="0.000143890"/>
    </inertial>
      <visual>
        <geometry>
          <mesh filename="meshes_tello/SHANK.dae" scale="1 1 1"/>
        </geometry>
        <origin rpy="0.0 0.0 0.0" xyz="0.0 0.0 0.0"/>
    </visual>
  </link>

  <joint name="r_ankle" type="continuous">
    <axis xyz="0 1 0"/>
    <!-- <origin rpy="0 0 0" xyz="0.0 0.0 -0.47"/> -->
    <origin rpy="0 0 0" xyz="0.0 0.0 -0.2276"/>
    <parent link="R_SHANK"/>
    <child link="R_Foot" />
  </joint>

  <link name="R_Foot">
    <inertial>
      <mass value="0.05552"/>
      <origin xyz="0.01067 0.0 -0.01226"/>
      <inertia ixx="0.000006734" ixy="0.0" ixz="0.000002630" iyy="0.000036387" iyz="0.0" izz="0.000032703"/>
    </inertial>
      <visual>
        <geometry>
          <mesh filename="meshes_tello/FOOT.dae" scale="1 1 1"/>
        </geometry>
        <origin rpy="0.0 0.0 0.0" xyz="0.0 0.0 0.0"/>
    </visual>
  </link>

  <!--!!!!!!!!!!!!!!!!!!!!!LEFT LEG!!!!!!!!!!!!!!!!!!!!!!!!!!!!!!!!!!!!!!!!!!!!!!!!-->
  <joint name="l_hip_yaw" type="continuous">
    <axis xyz="0 0 1"/>
    <origin rpy="0 0 0" xyz="0.0 0.090 -0.029"/>
    <parent link="torso"/>
    <child link="L_HIP_C"/>
  </joint>
  <link name="L_HIP_C">
    <inertial>
      <mass value="1.19633"/>
      <origin xyz="-0.00044 0.0 -0.05368"/>
      <inertia ixx="0.001961019" ixy="0.000000328" ixz="0.000040006" iyy="0.002434744" iyz="0.0" izz="0.001642970"/>
    </inertial>
      <visual>
        <geometry>
          <mesh filename="meshes_tello/HIP_C.dae" scale="1 1 1"/>
        </geometry>
        <origin rpy="0.0 0.0 0.0" xyz="0.0 0.0 0.0"/>
    </visual>
 </link>

  <joint name="l_hip_roll" type="continuous">
    <axis xyz="1 0 0"/>
    <origin rpy="0.0 0.0 0.0" xyz="0.0 0.0 -0.175"/>
    <parent link="L_HIP_C"/>
    <child link="L_HIP_GIMBAL"/>
  </joint>
  <link name="L_HIP_GIMBAL">
    <inertial>
      <mass value="0.26433"/>
      <origin xyz="-0.00152 0.0 0.01677"/>
      <inertia ixx="0.000735018" ixy="0.0" ixz="0.000001772" iyy="0.000715107" iyz="0.000000002" izz="0.000728669"/>
    </inertial>
      <visual>
        <geometry>
          <mesh filename="meshes_tello/HIP_GIMBAL.dae" scale="1 1 1"/>
        </geometry>
        <origin rpy="0.0 0.0 0.0" xyz="0.0 0.0 0.0"/>
    </visual>
 </link>

  <joint name="l_hip_pitch" type="continuous">
    <axis xyz="0 1 0"/>
    <origin rpy="0.0 0 0.0" xyz="0.0 0.0 -0.022"/>
    <parent link="L_HIP_GIMBAL"/>
    <child link="L_THIGH"/>
  </joint>

  <link name="L_THIGH">
    <inertial>
      <mass value="2.111"/>
      <origin xyz="-0.00525 0.00011 -0.03179"/>
      <inertia ixx="0.012171016" ixy="-0.000013456" ixz="-0.000145044" iyy="0.011789322" iyz="0.000027517" izz="0.003575467"/>
    </inertial>
     <visual>
       <geometry>
         <mesh filename="meshes_tello/THIGH.dae" scale="1 1 1"/>
       </geometry>
       <origin rpy="0.0 0.0 0.0" xyz="0.0 0.0 0.0"/>
    </visual>
  </link>

  <joint name="l_knee" type="continuous">
    <axis xyz="0 1 0"/>
    <!-- <origin rpy="0 0 0" xyz="0.0 0.0 -0.47"/> -->
    <origin rpy="0 0 0" xyz="0.0 0.0 -0.2276"/>
    <parent link="L_THIGH"/>
    <child link="L_SHANK" />
  </joint>

  <link name="L_SHANK">
    <inertial>
      <mass value="0.37773"/>
      <origin xyz="0.00396 -0.00016 -0.098.34"/>
      <inertia ixx="0.001797413" ixy="0.000002934" ixz="0.000019506" iyy="0.001815537" iyz="0.000003553" izz="0.000143890"/>
    </inertial>
      <visual>
        <geometry>
          <mesh filename="meshes_tello/SHANK.dae" scale="1 1 1"/>
        </geometry>
        <origin rpy="0.0 0.0 0.0" xyz="0.0 0.0 0.0"/>
    </visual>
  </link>

  <joint name="l_ankle" type="continuous">
    <axis xyz="0 1 0"/>
    <!-- <origin rpy="0 0 0" xyz="0.0 0.0 -0.47"/> -->
    <origin rpy="0 0 0" xyz="0.0 0.0 -0.2276"/>
    <parent link="L_SHANK"/>
    <child link="L_Foot" />
  </joint>

  <link name="L_Foot">
    <inertial>
      <mass value="0.05552"/>
      <origin xyz="0.01067 0.0 -0.01226"/>
      <inertia ixx="0.000006734" ixy="0.0" ixz="0.000002630" iyy="0.000036387" iyz="0.0" izz="0.000032703"/>
    </inertial>
      <visual>
        <geometry>
          <mesh filename="meshes_tello/FOOT.dae" scale="1 1 1"/>
        </geometry>
        <origin rpy="0.0 0.0 0.0" xyz="0.0 0.0 0.0"/>
    </visual>
  </link>

  <!--!!!!!!!!!!!!!!!!!!!!!RIGHT ARM!!!!!!!!!!!!!!!!!!!!!!!!!!!!!!!!!!!!!!!!!!!!!!!!-->
  <joint name="torso_to_R_ShoulderRx" type="continuous">
    <axis xyz="1 0 0"/>
    <origin rpy="0 0 0" xyz="-0.0215 -0.1115 0.202"/>
    <parent link="torso"/>
    <child link="R_ShoulderRx"/>
  </joint>
  <link name="R_ShoulderRx">
    <inertial>
      <mass value="0.30"/>
      <origin xyz="0.01 0.0 0.0"/>
      <inertia ixx="0.003735" ixy="0.0" ixz="0.0" iyy="0.01391" iyz="0.0" izz="0.01355"/>
    </inertial>
    <visual>
      <geometry>
        <mesh filename="meshes/ShoulderRx.dae" scale="1 1 1"/>
      </geometry>
      <origin rpy="-1.5707 0 0.0" xyz="0. 0. 0"/>
    </visual>
   </link>

  <joint name="R_ShoulderRx_to_R_UpperArm" type="continuous">
    <axis xyz="0 1 0"/>
    <origin rpy="0 0 0" xyz="0.0545 0.0 0.0"/>
    <parent link="R_ShoulderRx"/>
    <child link="R_UpperArm"/>
  </joint>
  <link name="R_UpperArm">
    <inertial>
      <mass value="0.37"/>
      <origin xyz="0.0 0.0 -0.09"/>
      <inertia ixx="0.003735" ixy="0.0" ixz="0.0" iyy="0.01391" iyz="0.0" izz="0.01355"/>
    </inertial>
    <visual>
      <geometry>
        <mesh filename="meshes/UpperArm.dae" scale="1 1 1"/>
      </geometry>
      <origin rpy="-1.5707 0 0.0" xyz="0. 0. 0"/>
    </visual>
  </link>

  <joint name="R_UpperArm_to_R_ForeArm" type="continuous">
    <axis xyz="0 1 0"/>
    <origin rpy="0 0 0" xyz="0.0 -0.068 -0.195"/>
    <parent link="R_UpperArm"/>
    <child link="R_ForeArm"/>
  </joint>
  <link name="R_ForeArm">
    <inertial>
      <mass value="0.1"/>
      <origin xyz="0.0 0.0 -0.04"/>
      <inertia ixx="0.003735" ixy="0.0" ixz="0.0" iyy="0.01391" iyz="0.0" izz="0.01355"/>
    </inertial>
    <visual>
      <geometry>
         <mesh filename="meshes/ForeArm2.dae" scale="1 1 1"/>
      </geometry>
      <origin rpy="-1.5707 0 0" xyz="0.0 0.0 0"/>
    </visual>
  </link>

  <!--!!!!!!!!!!!!!!!!!!!!!LEFT ARM!!!!!!!!!!!!!!!!!!!!!!!!!!!!!!!!!!!!!!!!!!!!!!!!-->
  <joint name="torso_to_L_ShoulderRx" type="continuous">
    <axis xyz="1 0 0"/>
    <origin rpy="0 0 0" xyz="-0.0215 0.1115 0.202"/>
    <parent link="torso"/>
    <child link="L_ShoulderRx"/>
  </joint>
  <link name="L_ShoulderRx">
    <inertial>
      <mass value="0.30"/>
      <origin xyz="0.01 0.0 0.0"/>
      <inertia ixx="0.003735" ixy="0.0" ixz="0.0" iyy="0.01391" iyz="0.0" izz="0.01355"/>
    </inertial>
    <visual>
      <geometry>
        <mesh filename="meshes/ShoulderRx.dae" scale="1 1 1"/>
      </geometry>
      <origin rpy="-1.5707 0 0.0" xyz="0. 0. 0"/>
    </visual>
   </link>

  <joint name="L_ShoulderRx_to_L_UpperArm" type="continuous">
    <axis xyz="0 1 0"/>
    <origin rpy="0 0 0" xyz="0.0545 0.0 0.0"/>
    <parent link="L_ShoulderRx"/>
    <child link="L_UpperArm"/>
  </joint>
  <link name="L_UpperArm">
    <inertial>
      <mass value="0.37"/>
      <origin xyz="0.0 0.0 -0.09"/>
      <inertia ixx="0.003735" ixy="0.0" ixz="0.0" iyy="0.01391" iyz="0.0" izz="0.01355"/>
    </inertial>
    <visual>
      <geometry>
        <mesh filename="meshes/UpperArm.dae" scale="1 1 1"/>
      </geometry>
      <origin rpy="-1.5707 0 3.141592" xyz="0. 0. 0"/>
    </visual>
  </link>

  <joint name="L_UpperArm_to_L_ForeArm" type="continuous">
    <axis xyz="0 1 0"/>
    <origin rpy="0 0 0" xyz="0.0 0.068 -0.195"/>
    <parent link="L_UpperArm"/>
    <child link="L_ForeArm"/>
  </joint>
  <link name="L_ForeArm">
    <inertial>
      <mass value="0.1"/>
      <origin xyz="0.0 0.0 -0.04"/>
      <inertia ixx="0.003735" ixy="0.0" ixz="0.0" iyy="0.01391" iyz="0.0" izz="0.01355"/>
    </inertial>
    <visual>
      <geometry>
         <mesh filename="meshes/ForeArm2.dae" scale="1 1 1"/>
      </geometry>
      <origin rpy="-1.5707 0 0" xyz="0.0 0.0 0"/>
    </visual>
  </link>
</robot>
