<robot name="TELLO" xmlns:xacro="http://ros.org/wiki/xacro">
  <!-- ===== DUMMY 'BASE' LINK ==== -->
  <link name="BODY">
    <inertial>
      <mass value="9.807"/>
      <origin xyz="0.0 0.0 0.1345"/>
      <inertia ixx="0.188824827" ixy="0.000008407" ixz="-0.000015445" iyy="0.083219132" iyz="	0.000010634" izz="0.119998911"/>
    </inertial>
    <visual>
      <geometry>
        <mesh filename="meshes/BODY.dae" scale="1 1 1"/>
      </geometry>
      <origin rpy="0.0 0.0 0.0" xyz="0.0 0.0 0.0"/>
    </visual>
  </link>
  <!--!!!!!!!!!!!!!!!!!!!!!RIGHT LEG!!!!!!!!!!!!!!!!!!!!!!!!!!!!!!!!!!!!!!!!!!!!!!!!-->
  <joint name="torso_to_R_HipRz" type="continuous">
    <axis xyz="0 0 1"/>
    <origin rpy="0 0 0" xyz="0.0 -0.075 0.0"/>
    <parent link="BODY"/>
    <child link="R_HipRz"/>
  </joint>
  <link name="R_HipRz">
    <inertial>
      <mass value="0.30"/>
      <origin xyz="0.0 0.00 -0.04293"/>
      <inertia ixx="0.003735" ixy="0.0" ixz="0.0" iyy="0.01391" iyz="0.0" izz="0.01355"/>
    </inertial>
    <visual>
      <geometry>
         <mesh filename="meshes_humanoid/HipRz.dae" scale="1 1 1"/>
      </geometry>
      <origin rpy="-1.5707 0 0.0" xyz="0. 0. 0"/>
    </visual>
   </link>

  <joint name="R_HipRz_to_R_HipRx" type="continuous">
    <axis xyz="1 0 0"/>
    <origin rpy="0 0 0" xyz="-0.041 0.0 -0.0885"/>
    <parent link="R_HipRz"/>
    <child link="R_HipRx"/>
  </joint>
  <link name="R_HipRx">
    <inertial>
      <mass value="0.30"/>
      <origin xyz="0.0 0.0 -0.01"/>
      <inertia ixx="0.003735" ixy="0.0" ixz="0.0" iyy="0.01391" iyz="0.0" izz="0.01355"/>
    </inertial>
    <visual>
      <geometry>
         <mesh filename="meshes_humanoid/HipRx.dae" scale="1 1 1"/>
      </geometry>
      <origin rpy="-1.5707 0 0.0" xyz="0. 0. 0"/>
    </visual>
   </link>

  <joint name="R_HipRx_to_R_Thigh" type="continuous">
    <axis xyz="0 1 0"/>
    <origin rpy="0 0 0" xyz="0.065 0.0 0.0"/>
    <parent link="R_HipRx"/>
    <child link="R_Thigh"/>
  </joint>
  <link name="R_Thigh">
    <inertial>
      <mass value="1.0"/>
      <origin xyz="0.0 0.0 -0.10"/>
      <inertia ixx="0.003735" ixy="0.0" ixz="0.0" iyy="0.01391" iyz="0.0" izz="0.01355"/>
    </inertial>
    <visual>
        <geometry>
          <mesh filename="meshes_humanoid/Thigh.dae" scale="1 1 1"/>
     </geometry>
      <origin rpy="-1.5707 0 0" xyz="0.0 0.0 0.0"/>
    </visual>
   </link>

  <joint name="R_Knee" type="continuous">
    <axis xyz="0 1 0"/>
    <origin rpy="0 0 0" xyz="0.0 0.017875 -0.247"/>
    <parent link="R_Thigh"/>
    <child link="R_Shank"/>
  </joint>
  <link name="R_Shank">
    <inertial>
      <mass value="0.70"/>
      <origin xyz="-0.03416 -0.00075 -0.01"/>
      <inertia ixx="0.003735" ixy="0.0" ixz="0.0" iyy="0.01391" iyz="0.0" izz="0.01355"/>
    </inertial>
    <visual>
      <geometry>
         <mesh filename="meshes_humanoid/LowerLeg3_drawing.dae" scale="1 1 1"/>
      </geometry>
      <origin rpy="-1.5707 0 0.0" xyz="0. 0. 0"/>
    </visual>
  </link>

  <joint name="R_Ankle" type="continuous">
    <axis xyz="0 1 0"/>
    <origin rpy="0 0 0" xyz="0.0 0.0 -0.247"/>
    <parent link="R_Shank"/>
    <child link="R_FOOT"/>
  </joint>
  <link name="R_FOOT">
    <inertial>
      <mass value="0.30"/>
      <origin xyz="0.0 0.0 -0.01"/>
      <inertia ixx="0.003735" ixy="0.0" ixz="0.0" iyy="0.01391" iyz="0.0" izz="0.01355"/>
    </inertial>
    <visual>
      <geometry>
        <mesh filename="meshes_humanoid/foot_drawing.dae" scale="1 1 1"/>
      </geometry>
      <origin rpy="-1.5707 0 0.0" xyz="0. 0. 0"/>
    </visual>
  </link>


  <!--!!!!!!!!!!!!!!!!!!!!!LEFT LEG!!!!!!!!!!!!!!!!!!!!!!!!!!!!!!!!!!!!!!!!!!!!!!!!-->
  <joint name="torso_to_L_HipRz" type="continuous">
    <axis xyz="0 0 1"/>
    <origin rpy="0 0 0" xyz="0.0 0.075 0.0"/>
    <parent link="BODY"/>
    <child link="L_HipRz"/>
  </joint>
  <link name="L_HipRz">
    <inertial>
      <mass value="0.30"/>
      <origin xyz="0.0 0.00 -0.04293"/>
      <inertia ixx="0.003735" ixy="0.0" ixz="0.0" iyy="0.01391" iyz="0.0" izz="0.01355"/>
    </inertial>
    <visual>
      <geometry>
         <mesh filename="meshes_humanoid/HipRz.dae" scale="1 1 1"/>
      </geometry>
      <origin rpy="-1.5707 0 0.0" xyz="0. 0. 0"/>
    </visual>
   </link>

  <joint name="L_HipRz_to_L_HipRx" type="continuous">
    <axis xyz="1 0 0"/>
    <origin rpy="0 0 0" xyz="-0.041 0.0 -0.0885"/>
    <parent link="L_HipRz"/>
    <child link="L_HipRx"/>
  </joint>
  <link name="L_HipRx">
    <inertial>
      <mass value="0.30"/>
      <origin xyz="0.0 0.0 -0.01"/>
      <inertia ixx="0.003735" ixy="0.0" ixz="0.0" iyy="0.01391" iyz="0.0" izz="0.01355"/>
    </inertial>
    <visual>
      <geometry>
         <mesh filename="meshes_humanoid/HipRx.dae" scale="1 1 1"/>
      </geometry>
      <origin rpy="1.5707 0 0" xyz="0. 0. 0"/>
    </visual>
   </link>

  <joint name="L_HipRx_to_L_Thigh" type="continuous">
    <axis xyz="0 1 0"/>
    <origin rpy="0 0 0" xyz="0.065 0.0 0.0"/>
    <parent link="L_HipRx"/>
    <child link="L_Thigh"/>
  </joint>
  <link name="L_Thigh">
    <inertial>
      <mass value="1.0"/>
      <origin xyz="0.0 0.0 -0.10"/>
      <inertia ixx="0.003735" ixy="0.0" ixz="0.0" iyy="0.01391" iyz="0.0" izz="0.01355"/>
    </inertial>
    <visual>
        <geometry>
          <mesh filename="meshes_humanoid/Thigh.dae" scale="1 1 1"/>
     </geometry>
      <origin rpy="-1.5707 0 3.141592" xyz="0.0 0.0 0.0"/>
    </visual>
   </link>

  <joint name="L_Knee" type="continuous">
    <axis xyz="0 1 0"/>
    <origin rpy="0 0 0" xyz="0.0 -0.017875 -0.247"/>
    <parent link="L_Thigh"/>
    <child link="L_Shank"/>
  </joint>
  <link name="L_Shank">
    <inertial>
      <mass value="0.70"/>
      <origin xyz="-0.03416 -0.00075 -0.01"/>
      <inertia ixx="0.003735" ixy="0.0" ixz="0.0" iyy="0.01391" iyz="0.0" izz="0.01355"/>
    </inertial>
    <visual>
      <geometry>
         <mesh filename="meshes_humanoid/LowerLeg3_drawing.dae" scale="1 1 1"/>
      </geometry>
      <origin rpy="-1.5707 0 0.0" xyz="0. 0. 0"/>
    </visual>
  </link>

  <joint name="L_Ankle" type="continuous">
    <axis xyz="0 1 0"/>
    <origin rpy="0 0 0" xyz="0.0 0.0 -0.247"/>
    <parent link="L_Shank"/>
    <child link="L_FOOT"/>
  </joint>
  <link name="L_FOOT">
    <inertial>
      <mass value="0.30"/>
      <origin xyz="0.0 0.0 -0.01"/>
      <inertia ixx="0.003735" ixy="0.0" ixz="0.0" iyy="0.01391" iyz="0.0" izz="0.01355"/>
    </inertial>
    <visual>
      <geometry>
        <mesh filename="meshes_humanoid/foot_drawing.dae" scale="1 1 1"/>
      </geometry>
      <origin rpy="-1.5707 0 0.0" xyz="0. 0. 0"/>
    </visual>
  </link>

</robot>
