<?xml version="1.0" ?>
<robot name="draco" xmlns:xacro="http://ros.org/wiki/xacro">

    <link name="world"/>
    
    <joint name="ground_joint" type="floating">
        <origin xyz="0 0 0.15" rpy="0 0 0" />
        <parent link="world" />
        <child link="hori_stage" />
    </joint>


    <link name="hori_stage">
        <inertial>
            <origin rpy="0 0 0" xyz="0 0 0"/>
            <mass value="11.313"/>
            <inertia ixx="0.25" ixy="-0.002" ixz="0.006" iyy="0.268" iyz="0.002" izz="0.114"/>
        </inertial>
        <visual>
            <origin rpy="1.57 0 1.570" xyz = "0.5 -0.90 0.505"/>
            <geometry>
                <mesh filename="meshes/hori_stage_edit.3ds" scale="0.001 0.001 0.001"/>
            </geometry>
        </visual>
        <!--<collision>-->
            <!--<origin rpy="1.57 0 1.570" xyz = "0.5 -0.90 0.505"/>-->
            <!--<geometry>-->
                <!--<mesh filename="meshes/hori_stage_edit.3ds" scale="0.001 0.001 0.001"/>-->
            <!--</geometry>-->
        <!--</collision>-->
    </link>

    <joint name="hori-vertical" type="continuous">
        <origin rpy="0.0 0.0 0.0" xyz="-0.017 -0.3207 1.315"/>
        <axis xyz="0 1 0"/>
        <parent link="hori_stage"/>
        <child link="vertical_stage"/>
    </joint>

    <link name="vertical_stage">
        <inertial>
            <origin rpy="0 0 0" xyz="0.0061 0 -0.00002473"/>
            <mass value="5.4818"/>
            <inertia ixx="0.0777" ixy="-0.0001" ixz="-0.0005" iyy="0.0761" iyz="0.0084" izz="0.0061"/>
        </inertial>
        <visual>
            <origin rpy="-1.570 0.014 0.00" xyz="-0.0 -0.00 0.0"/>
            <geometry>
                <mesh filename="meshes/vertical_plate_edit.3ds" scale="0.001 0.001 0.001"/>
            </geometry>
        </visual>
        <!--<collision>-->
            <!--<origin rpy="0 3.14 -1.57" xyz="-0.0735 -0.087 0.03"/>-->
            <!--<geometry>-->
                <!--<mesh filename="meshes/upperLeg.STL" scale="0.001 0.001 0.001"/>-->
            <!--</geometry>-->
        <!--</collision>-->
    </link>

    <!--<joint name="kneePitch" type="continuous">-->
        <!--<origin rpy="0.0 0.0 0.0" xyz="0 0 -0.49"/>-->
        <!--<axis xyz="0 1 0"/>-->
        <!--<parent link="upperLeg"/>-->
        <!--<child link="lowerLeg"/>-->
    <!--</joint>-->

    <!--<link name="lowerLeg">-->
        <!--<inertial>-->
            <!--<origin rpy="0 0 0" xyz="-0.0038 -0.0022 -0.2647"/>-->
            <!--<mass value="3.7701"/>-->
            <!--<inertia ixx="0.0777" ixy="-0.0001" ixz="-0.0005" iyy="0.0761" iyz="0.0084" izz="0.0061"/>-->
        <!--</inertial>-->
        <!--<visual>-->
            <!--<origin rpy="0 0 -1.57" xyz="-0.075 0.05 -0.513"/>-->
            <!--<geometry>-->
                <!--<mesh filename="meshes/lowerLeg.STL" scale="0.001 0.001 0.001"/>-->
            <!--</geometry>-->
        <!--</visual>-->
        <!--<collision>-->
            <!--<origin rpy="0 0 -1.57" xyz="-0.075 0.05 -0.513"/>-->
            <!--<geometry>-->
                <!--<mesh filename="meshes/lowerLeg.STL" scale="0.001 0.001 0.001"/>-->
            <!--</geometry>-->
        <!--</collision>-->
    <!--</link>-->

    <!--<joint name="ankle" type="continuous">-->
        <!--<origin rpy="0.0 0.0 0.0" xyz="0 0 -0.49"/>-->
        <!--<axis xyz="0 1 0"/>-->
        <!--<parent link="lowerLeg"/>-->
        <!--<child link="foot"/>-->
    <!--</joint>-->

    <!--<link name="foot">-->
        <!--<inertial>-->
            <!--<origin rpy="0 0 0" xyz="0.0183 0 -0.0232"/>-->
            <!--<mass value="0.6817573"/>-->
            <!--<inertia ixx="0.001766" ixy="-0.0000003" ixz="0.0000006" iyy="0.0020957" iyz="-0.0001134" izz="0.0004916"/>-->
        <!--</inertial>-->
        <!--<visual>-->
            <!--<origin rpy="1.57 0 1.57" xyz="0 0 0"/>-->
            <!--<origin rpy="1.57 0 1.57" xyz="-0.07 -0.05 -0.03"/>-->
            <!--<geometry>-->
                <!--<mesh filename="meshes/foot.STL" scale="0.001 0.001 0.001"/>-->
            <!--</geometry>-->
        <!--</visual>-->
        <!--<collision>-->
            <!--<origin rpy="1.57 0 1.57" xyz="-0.07 -0.05 -0.03"/>-->
            <!--<geometry>-->
                <!--<mesh filename="meshes/foot.STL" scale="0.001 0.001 0.001"/>-->
            <!--</geometry>-->
        <!--</collision>-->
    <!--</link>-->


</robot>
