<?xml version="1.0" ?>
<!-- =================================================================================== -->
<!-- |    This document was autogenerated by xacro from hume/xacro/hume.xacro          | -->
<!-- |    EDITING THIS FILE BY HAND IS NOT RECOMMENDED                                 | -->
<!-- =================================================================================== -->
<robot name="hume" xmlns:xacro="http://ros.org/wiki/xacro">
  <!-- ===== DUMMY 'BASE' LINK ==== -->
  <link name="torso">
    <inertial>
      <mass value="12.61"/>
      <origin xyz="0.00347 0.0 0.22524"/>
      <inertia ixx="0.3006167" ixy="0" ixz="0" iyy="0.23837" iyz="0" izz="0.09690467"/>
    </inertial>
  </link>
  <!-- IMU -->
  <joint name="fixed_imu" type="fixed">
    <axis xyz="0 1 0"/>
    <origin rpy="0 0 0" xyz="0.0 0.07 0.22"/>
    <parent link="torso"/>
    <child link="imu" />
  </joint>
  <link name="imu">
    <inertial>
      <mass value="0.0000000000001"/>
      <origin xyz="0.0 0.0 0.0"/>
      <inertia ixx="0.0000000001" ixy="0" ixz="0.0" iyy="0.000000001" iyz="0" izz="0.00000000001"/>
    </inertial>
  </link>  
  <!--!!!!!!!!!!!!!!!!!!!!! LED !!!!!!!!!!!!!!!!!!!!!!!!!!!!!!!!!!-->
  <!-- LED_BODY_0: attached on the body -->
  <!-- <joint name="fixed_body_led0" type="fixed"> -->
  <!--   <axis xyz="0 1 0"/> -->
  <!--   <origin rpy="0 0 0" xyz="-0.075 0.0 0.2"/> -->
  <!--   <parent link="torso"/> -->
  <!--   <child link="body_led0" /> -->
  <!-- </joint> -->
  <!-- <link name="body_led0"> -->
  <!--   <inertial> -->
  <!--     <mass value="0.000000000001"/> -->
  <!--     <origin xyz="0.0 0.0 0.0"/> -->
  <!--     <inertia ixx="0.000000001" ixy="0" ixz="0.0" iyy="0.0000000001" iyz="0" izz="0.00000000001"/> -->
  <!--   </inertial> -->
  <!-- </link> -->
  <!-- LED_BODY_1: attached on the body -->
  <!-- <joint name="fixed_body_led1" type="fixed"> -->
  <!--   <axis xyz="0 1 0"/> -->
  <!--   <origin rpy="0 0 0" xyz="0.07 0.0 0.2"/> -->
  <!--   <parent link="torso"/> -->
  <!--   <child link="body_led1" /> -->
  <!-- </joint> -->
  <!-- <link name="body_led1"> -->
  <!--   <inertial> -->
  <!--     <mass value="0.000000000001"/> -->
  <!--     <origin xyz="0.0 0.0 0.0"/> -->
  <!--     <inertia ixx="0.0000000001" ixy="0" ixz="0.0" iyy="0.0000000001" iyz="0" izz="0.00000000001"/> -->
  <!--   </inertial> -->
  <!-- </link> -->
  <!-- LED_BODY_2: attached on the body -->
  <!-- <joint name="fixed_body_led2" type="fixed"> -->
  <!--   <axis xyz="0 1 0"/> -->
  <!--   <origin rpy="0 0 0" xyz="0.075 0.0 0.0"/> -->
  <!--   <parent link="torso"/> -->
  <!--   <child link="body_led2" /> -->
  <!-- </joint> -->
  <!-- <link name="body_led2"> -->
  <!--   <inertial> -->
  <!--     <mass value="0.0000000000001"/> -->
  <!--     <origin xyz="0.0 0.0 0.0"/> -->
  <!--     <inertia ixx="0.00000000001" ixy="0" ixz="0.0" iyy="0.0000000001" iyz="0" izz="0.00000000001"/> -->
  <!--   </inertial> -->
  <!-- </link> -->
  <!-- LED_BODY_3: attached on the body -->
  <joint name="fixed_body_led3" type="fixed">
    <axis xyz="0 1 0"/>
    <origin rpy="0 0 0" xyz="0.07 0.14 0.38"/>
    <parent link="torso"/>
    <child link="body_led3" />
  </joint>
  <link name="body_led3">
    <inertial>
      <mass value="0.0000000000001"/>
      <origin xyz="0.0 0.0 0.0"/>
      <inertia ixx="0.00000000001" ixy="0" ixz="0.0" iyy="0.0000000001" iyz="0" izz="0.00000000001"/>
    </inertial>
  </link>
  <!-- LED_BODY_4: attached on the body -->
  <joint name="fixed_body_led4" type="fixed">
    <axis xyz="0 1 0"/>
    <origin rpy="0 0 0" xyz="-0.07 0.14 0.38"/>
    <parent link="torso"/>
    <child link="body_led4" />
  </joint>
  <link name="body_led4">
    <inertial>
      <mass value="0.0000000000001"/>
      <origin xyz="0.0 0.0 0.0"/>
      <inertia ixx="0.00000000001" ixy="0" ixz="0.0" iyy="0.0000000001" iyz="0" izz="0.00000000001"/>
    </inertial>
  </link>
  <!-- LED_BODY_5: attached on the body -->
  <joint name="fixed_body_led5" type="fixed">
    <axis xyz="0 1 0"/>
    <origin rpy="0 0 0" xyz="-0.07 -0.14 0.38"/>
    <parent link="torso"/>
    <child link="body_led5" />
  </joint>
  <link name="body_led5">
    <inertial>
      <mass value="0.0000000000001"/>
      <origin xyz="0.0 0.0 0.0"/>
      <inertia ixx="0.00000000001" ixy="0" ixz="0.0" iyy="0.0000000001" iyz="0" izz="0.00000000001"/>
    </inertial>
  </link>
  <!-- LED_BODY_6: attached on the body -->
  <joint name="fixed_body_led6" type="fixed">
    <axis xyz="0 1 0"/>
    <origin rpy="0 0 0" xyz="0.07 -0.14 0.38"/>
    <parent link="torso"/>
    <child link="body_led6" />
  </joint>
  <link name="body_led6">
    <inertial>
      <mass value="0.0000000000001"/>
      <origin xyz="0.0 0.0 0.0"/>
      <inertia ixx="0.00000000001" ixy="0" ixz="0.0" iyy="0.0000000001" iyz="0" izz="0.00000000001"/>
    </inertial>
  </link>
  
  <!--!!!!!!!!!!!!!!!!!!!!!RIGHT LEG!!!!!!!!!!!!!!!!!!!!!!!!!!!!!!!!!!!!!!!!!!!!!!!!-->
  <joint name="1_torso_to_abduct_r_j" type="continuous">
    <axis xyz="1 0 0"/>
    <origin rpy="0 0 0" xyz="0.0 -0.1397 0.0"/>
    <parent link="torso"/>
    <child link="abduct_r"/>
  </joint>
  <link name="abduct_r">
    <inertial>
      <mass value="2.1656"/>
      <origin xyz="-0.03416 -0.00075 0.04293"/>
      <inertia ixx="0.003735" ixy="0.0" ixz="0.0" iyy="0.01391" iyz="0.0" izz="0.01355"/>
    </inertial>
  </link>

  <joint name="abduct_r_to_thigh_r_j" type="continuous">
    <axis xyz="0 1 0"/>
    <origin rpy="0 0 0.05974278" xyz="0.0 0.0 -0.03535"/>
    <parent link="abduct_r"/>
    <child link="thigh_r"/>
  </joint>
  <link name="thigh_r">
    <inertial>
      <mass value="3.0"/>
      <origin xyz="-0.00396 0.000018 -0.16"/>
      <inertia ixx="0.038482" ixy="0" ixz="0.0" iyy="0.039835" iyz="-0.003" izz="0.0042934"/>
    </inertial>
  </link>

  <joint name="thigh_r_to_knee_r_j" type="continuous">
    <axis xyz="0 1 0"/>
    <origin rpy="0 0 -0.05974278" xyz="0.0181 0.0 -0.4575"/>
    <parent link="thigh_r"/>
    <child link="shank_r"/>
  </joint>
  <link name="shank_r">
    <inertial>
      <mass value="0.21"/>
      <origin xyz="0.0 0.0 -0.31"/>
      <inertia ixx="0.00338" ixy="0" ixz="0.0" iyy="0.00338" iyz="0" izz="0.000011"/>
    </inertial>
  </link>
  <!-- <link name="shank_r"> -->
  <!--   <inertial> -->
  <!--     <mass value="0.31"/> -->
  <!--     <origin xyz="0.0 0.0 -0.168"/> -->
  <!--     <inertia ixx="0.00538" ixy="0" ixz="0.0" iyy="0.00538" iyz="0" izz="0.000011"/> -->
  <!--   </inertial> -->
  <!-- </link> -->

  <joint name="fixed_rfoot" type="fixed">
    <axis xyz="0 1 0"/>
    <origin rpy="0 0 0" xyz="0.0 0.0 -0.440"/>
    <parent link="shank_r"/>
    <child link="rfoot" />
  </joint>
  <link name="rfoot">
    <inertial>
      <mass value="0.000000000001"/>
      <origin xyz="0.0 0.0 0.0"/>
      <inertia ixx="0.000000001" ixy="0" ixz="0.0" iyy="0.00000000338" iyz="0" izz="0.000000000011"/>
    </inertial>
  </link>
  <!-- <joint name="fixed_rfoot" type="fixed"> -->
  <!--   <axis xyz="0 1 0"/> -->
  <!--   <origin rpy="0 0 0" xyz="0.0 0.0 -0.320"/> -->
  <!--   <parent link="shank_r"/> -->
  <!--   <child link="rfoot" /> -->
  <!-- </joint> -->
  <!-- <link name="rfoot"> -->
  <!--   <inertial> -->
  <!--     <mass value="4.84"/> -->
  <!--     <origin xyz="0.0 0.0 0.0"/> -->
  <!--     <inertia ixx="0.000000001" ixy="0" ixz="0.0" iyy="0.0000002" iyz="0" izz="0.000000000011"/> -->
  <!--   </inertial> -->
  <!-- </link> -->
  
      <!--!!!!!!!!!!!!!!!!!!!!!left LEG!!!!!!!!!!!!!!!!!!!!!!!!!!!!!!!!!!!!!!!!!!!!!!!!-->
  <joint name="2_torso_to_abduct_l_j" type="continuous">
    <axis xyz="1 0 0"/>
    <origin rpy="0 0 0" xyz="0.0 0.1397 0.0"/>
    <parent link="torso"/>
    <child link="abduct_l"/>
  </joint>
  <link name="abduct_l">
    <inertial>
      <mass value="2.1656"/>
      <origin xyz="-0.03416 0.00075 0.04293"/>
      <inertia ixx="0.003735" ixy="0.0" ixz="0.0" iyy="0.01391" iyz="0.0" izz="0.01355"/>
    </inertial>
  </link>

  <joint name="abduct_l_to_thigh_l_j" type="continuous">
    <axis xyz="0 1 0"/>
    <origin rpy="0 0 0.0447249" xyz="0.0 0.0 -0.03535"/>
    <parent link="abduct_l"/>
    <child link="thigh_l"/>
  </joint>
  <link name="thigh_l">
    <inertial>
      <mass value="3.0"/>
      <origin xyz="-0.00396 -0.000018 -0.16"/>
      <inertia ixx="0.038482" ixy="0" ixz="0.0" iyy="0.039835" iyz="0" izz="0.0042934"/>

    </inertial>
  </link>

  <joint name="thigh_l_to_knee_l_j" type="continuous">
    <axis xyz="0 1 0"/>
    <origin rpy="0 0 -0.00472424" xyz="0.0181 0.0 -0.4575"/>
    <parent link="thigh_l"/>
    <child link="shank_l"/>
    <!--    <dynamics damping="1.0"/>-->
  </joint>
  <link name="shank_l">
    <inertial>
      <mass value="0.201"/>
      <origin xyz="0.0 0.0 -0.31"/>
      <inertia ixx="0.00338" ixy="0" ixz="0.0" iyy="0.00338" iyz="0" izz="0.000011"/>
      
    </inertial>
  </link>
  <joint name="fixed_lfoot" type="fixed">
    <axis xyz="0 1 0"/>
    <origin rpy="0 0 0" xyz="0.0 0.0 -0.44"/>
    <parent link="shank_l"/>
    <child link="lfoot" />
  </joint>
  <link name="lfoot">
    <inertial>
      <mass value="0.000000000001"/>
      <origin xyz="0.0 0.0 0.0"/>
      <inertia ixx="0.000000001" ixy="0" ixz="0.0" iyy="0.00000000338" iyz="0" izz="0.000000000011"/>
    </inertial>
  </link>
  <!--!!!!!!!!!!!!!!!!!!!!! LED !!!!!!!!!!!!!!!!!!!!!!!!!!!!!!!!!!-->
  <!-- LED_0: attached on the body front -->
  <joint name="fixed_led0" type="fixed">
    <axis xyz="0 1 0"/>
    <origin rpy="0 0 0" xyz="0.07 0.0 -0.02"/>
    <parent link="torso"/>
    <child link="led0" />
  </joint>
  <link name="led0">
    <inertial>
      <mass value="0.000000000001"/>
      <origin xyz="0.0 0.0 0.0"/>
      <inertia ixx="0.000000001" ixy="0" ixz="0.0" iyy="0.00000000338" iyz="0" izz="0.000000000011"/>
    </inertial>
  </link>
  <!-- LED_1: On the left thigh upper -->
  <!-- <joint name="fixed_led1" type="fixed"> -->
  <!--   <axis xyz="0 1 0"/> -->
  <!--   <origin rpy="0 0 0" xyz="0.07 0.0 -0.1"/> -->
  <!--   <parent link="thigh_l"/> -->
  <!--   <child link="led1" /> -->
  <!-- </joint> -->
  <!-- <link name="led1"> -->
  <!--   <inertial> -->
  <!--     <mass value="0.000000000001"/> -->
  <!--     <origin xyz="0.0 0.0 0.0"/> -->
  <!--     <inertia ixx="0.000000001" ixy="0" ixz="0.0" iyy="0.00000000338" iyz="0" izz="0.000000000011"/> -->
  <!--   </inertial> -->
  <!-- </link>   -->
  <!-- LED_2: On the Left thigh lower -->
  <joint name="fixed_led2" type="fixed">
    <axis xyz="0 1 0"/>
    <origin rpy="0 0 0" xyz="0.07 0.0 -0.4"/>
    <parent link="thigh_l"/>
    <child link="led2" />
  </joint>
  <link name="led2">
    <inertial>
      <mass value="0.000000000001"/>
      <origin xyz="0.0 0.0 0.0"/>
      <inertia ixx="0.000000001" ixy="0" ixz="0.0" iyy="0.00000000338" iyz="0" izz="0.000000000011"/>
    </inertial>
  </link>  
  <!-- LED_3: On the Left shank upper -->
  <!-- <joint name="fixed_led3" type="fixed"> -->
  <!--   <axis xyz="0 1 0"/> -->
  <!--   <origin rpy="0 0 0" xyz="-0.013 0.0 -0.05"/> -->
  <!--   <parent link="shank_l"/> -->
  <!--   <child link="led3" /> -->
  <!-- </joint> -->
  <!-- <link name="led3"> -->
  <!--   <inertial> -->
  <!--     <mass value="0.000000000001"/> -->
  <!--     <origin xyz="0.0 0.0 0.0"/> -->
  <!--     <inertia ixx="0.000000001" ixy="0" ixz="0.0" iyy="0.00000000338" iyz="0" izz="0.000000000011"/> -->
  <!--   </inertial> -->
  <!-- </link>   -->
  <!-- LED_4: On the Left shank lower -->
  <joint name="fixed_led4" type="fixed">
    <axis xyz="0 1 0"/>
    <origin rpy="0 0 0" xyz="-0.02 0.0 -0.45"/>
    <parent link="shank_l"/>
    <child link="led4" />
  </joint>
  <link name="led4">
    <inertial>
      <mass value="0.000000000001"/>
      <origin xyz="0.0 0.0 0.0"/>
      <inertia ixx="0.000000001" ixy="0" ixz="0.0" iyy="0.00000000338" iyz="0" izz="0.000000000011"/>
    </inertial>
  </link>
  <!-- LED_5: attached on the body back -->
  <!-- <joint name="fixed_led5" type="fixed"> -->
  <!--   <axis xyz="0 1 0"/> -->
  <!--   <origin rpy="0 0 0" xyz="-0.07 0.0 -0.22524"/> -->
  <!--   <parent link="torso"/> -->
  <!--   <child link="led5" /> -->
  <!-- </joint> -->
  <!-- <link name="led5"> -->
  <!--   <inertial> -->
  <!--     <mass value="0.000000000001"/> -->
  <!--     <origin xyz="0.0 0.0 0.0"/> -->
  <!--     <inertia ixx="0.000000001" ixy="0" ixz="0.0" iyy="0.00000000338" iyz="0" izz="0.000000000011"/> -->
  <!--   </inertial> -->
  <!-- </link> -->
    <!-- LED_6: On the right thigh upper -->
  <!-- <joint name="fixed_led6" type="fixed"> -->
  <!--   <axis xyz="0 1 0"/> -->
  <!--   <origin rpy="0 0 0" xyz="0.07 0.0 -0.1"/> -->
  <!--   <parent link="thigh_r"/> -->
  <!--   <child link="led6" /> -->
  <!-- </joint> -->
  <!-- <link name="led6"> -->
  <!--   <inertial> -->
  <!--     <mass value="0.000000000001"/> -->
  <!--     <origin xyz="0.0 0.0 0.0"/> -->
  <!--     <inertia ixx="0.000000001" ixy="0" ixz="0.0" iyy="0.00000000338" iyz="0" izz="0.000000000011"/> -->
  <!--   </inertial> -->
  <!-- </link> -->
  <!-- LED_7: On the Right thigh lower -->
  <joint name="fixed_led7" type="fixed">
    <axis xyz="0 1 0"/>
    <origin rpy="0 0 0" xyz="0.07 0.0 -0.4"/>
    <parent link="thigh_r"/>
    <child link="led7" />
  </joint>
  <link name="led7">
    <inertial>
      <mass value="0.000000000001"/>
      <origin xyz="0.0 0.0 0.0"/>
      <inertia ixx="0.000000001" ixy="0" ixz="0.0" iyy="0.00000000338" iyz="0" izz="0.000000000011"/>
    </inertial>
  </link>  
  <!-- LED_8: On the Right Shank upper -->
  <!-- <joint name="fixed_led8" type="fixed"> -->
  <!--   <axis xyz="0 1 0"/> -->
  <!--   <origin rpy="0 0 0" xyz="-0.013 0.0 -0.05"/> -->
  <!--   <parent link="shank_r"/> -->
  <!--   <child link="led8" /> -->
  <!-- </joint> -->
  <!-- <link name="led8"> -->
  <!--   <inertial> -->
  <!--     <mass value="0.000000000001"/> -->
  <!--     <origin xyz="0.0 0.0 0.0"/> -->
  <!--     <inertia ixx="0.000000001" ixy="0" ixz="0.0" iyy="0.00000000338" iyz="0" izz="0.000000000011"/> -->
  <!--   </inertial> -->
  <!-- </link>   -->
  <!-- LED_9: On the Right Shank lower -->
  <joint name="fixed_led9" type="fixed">
    <axis xyz="0 1 0"/>
    <origin rpy="0 0 0" xyz="-0.02 0.0 -0.45"/>
    <parent link="shank_r"/>
    <child link="led9" />
  </joint>
  <link name="led9">
    <inertial>
      <mass value="0.000000000001"/>
      <origin xyz="0.0 0.0 0.0"/>
      <inertia ixx="0.000000001" ixy="0" ixz="0.0" iyy="0.00000000338" iyz="0" izz="0.000000000011"/>
    </inertial>
  </link>  
</robot>
